<?xml version="1.0" ?>
<!-- =================================================================================== -->
<!-- |    This document was autogenerated by xacro from mycobot_320.urdf.xacro         | -->
<!-- |    EDITING THIS FILE BY HAND IS NOT RECOMMENDED                                 | -->
<!-- =================================================================================== -->
<robot name="mycobot_320">
  <!--
    NOTE this is NOT a URDF. It cannot directly be loaded by consumers
    expecting a flattened '.urdf' file. See the top-level '.xacro' for that
    (but note that .xacro must still be processed by the xacro command).
  -->
  <!-- Create link fixed to the "world" -->
  <link name="world"/>
  <ros2_control name="mycobot_320" type="system">
    <hardware>
      <plugin>mock_components/GenericSystem</plugin>
    </hardware>
    <joint name="joint1">
      <command_interface name="position">
        <param name="min">-2.93</param>
        <param name="max">2.93</param>
      </command_interface>
      <state_interface name="position">
        <!-- Initial position for the GenericSystem and simulation -->
        <param name="initial_value">0.0</param>
      </state_interface>
      <!-- <state_interface name="velocity"/> -->
    </joint>
    <joint name="joint2">
      <command_interface name="position">
        <param name="min">-2.35</param>
        <param name="max">2.35</param>
      </command_interface>
      <state_interface name="position">
        <!-- Initial position for the GenericSystem and simulation -->
        <param name="initial_value">0.0</param>
      </state_interface>
      <!-- <state_interface name="velocity"/> -->
    </joint>
    <joint name="joint3">
      <command_interface name="position">
        <param name="min">-2.52</param>
        <param name="max">2.528</param>
      </command_interface>
      <state_interface name="position">
        <!-- Initial position for the GenericSystem and simulation -->
        <param name="initial_value">0.0</param>
      </state_interface>
      <!-- <state_interface name="velocity"/> -->
    </joint>
    <joint name="joint4">
      <command_interface name="position">
        <param name="min">-2.58</param>
        <param name="max">2.58</param>
      </command_interface>
      <state_interface name="position">
        <!-- Initial position for the GenericSystem and simulation -->
        <param name="initial_value">0.0</param>
      </state_interface>
      <!-- <state_interface name="velocity"/> -->
    </joint>
    <joint name="joint5">
      <command_interface name="position">
        <param name="min">-2.93</param>
        <param name="max">2.93</param>
      </command_interface>
      <state_interface name="position">
        <!-- Initial position for the GenericSystem and simulation -->
        <param name="initial_value">0.0</param>
      </state_interface>
      <!-- <state_interface name="velocity"/> -->
    </joint>
    <joint name="joint6">
      <command_interface name="position">
        <param name="min">-3.13</param>
        <param name="max">3.13</param>
      </command_interface>
      <state_interface name="position">
        <!-- Initial position for the GenericSystem and simulation -->
        <param name="initial_value">0.0</param>
      </state_interface>
      <!-- <state_interface name="velocity"/> -->
    </joint>
    <joint name="gripper_controller">
      <command_interface name="position">
        <param name="min">0</param>
        <param name="max">50</param>
      </command_interface>
      <state_interface name="position">
        <param name="initial_value">0</param>
      </state_interface>
    </joint>
  </ros2_control>
  <!-- <ros2_control name="ElectricGripper" type="system">
 <hardware>
   <plugin>mock_components/GenericSystem</plugin>
 </hardware>
 <joint name="gripper_controller">
   <command_interface name="position">
     <param name="min">0</param>
     <param name="max">50</param>
   </command_interface>
        <state_interface name="position">
          <param name="initial_value">0</param>
        </state_interface>
 </joint>
</ros2_control> -->
  <!-- links -  main serial chain -->
  <link name="base_link">
    <visual>
      <origin rpy="0 0 1.5708" xyz="0 0 0"/>
      <geometry>
        <mesh filename="file:///home/coconutros2/elephant_ws/install/mycobot_320_description/share/mycobot_320_description/meshes/mycobot_320/base.dae"/>
      </geometry>
    </visual>
    <collision>
      <origin rpy="0 0 1.5708" xyz="0 0 0"/>
      <geometry>
        <mesh filename="file:///home/coconutros2/elephant_ws/install/mycobot_320_description/share/mycobot_320_description/meshes/mycobot_320/base.dae"/>
      </geometry>
    </collision>
  </link>
  <link name="link1">
    <visual>
      <origin rpy=" 0 0 1.5708" xyz="0.0 0.0 -0.078 "/>
      <geometry>
        <mesh filename="file:///home/coconutros2/elephant_ws/install/mycobot_320_description/share/mycobot_320_description/meshes/mycobot_320/link1.dae"/>
      </geometry>
    </visual>
    <collision>
      <origin rpy=" 0 0 1.5708" xyz="0.0 0.0 -0.078 "/>
      <geometry>
        <mesh filename="file:///home/coconutros2/elephant_ws/install/mycobot_320_description/share/mycobot_320_description/meshes/mycobot_320/link1.dae"/>
      </geometry>
    </collision>
  </link>
  <link name="link2">
    <visual>
      <origin rpy=" 0 1.5708 0" xyz="0.0 0.0 -0.04 "/>
      <geometry>
        <mesh filename="file:///home/coconutros2/elephant_ws/install/mycobot_320_description/share/mycobot_320_description/meshes/mycobot_320/link2.dae"/>
      </geometry>
    </visual>
    <collision>
      <origin rpy=" 0 1.5708 0" xyz="0.0 0.0 -0.04 "/>
      <geometry>
        <mesh filename="file:///home/coconutros2/elephant_ws/install/mycobot_320_description/share/mycobot_320_description/meshes/mycobot_320/link2.dae"/>
      </geometry>
    </collision>
  </link>
  <link name="link3">
    <visual>
      <origin rpy=" 1.5708 1.5708 1.5708" xyz="0.0 0.0 0.039 "/>
      <geometry>
        <mesh filename="file:///home/coconutros2/elephant_ws/install/mycobot_320_description/share/mycobot_320_description/meshes/mycobot_320/link3.dae"/>
      </geometry>
    </visual>
    <collision>
      <origin rpy=" 1.5708 1.5708 1.5708" xyz="0.0 0.0 0.039 "/>
      <geometry>
        <mesh filename="file:///home/coconutros2/elephant_ws/install/mycobot_320_description/share/mycobot_320_description/meshes/mycobot_320/link3.dae"/>
      </geometry>
    </collision>
  </link>
  <link name="link4">
    <visual>
      <origin rpy=" 1.5708 1.5708 0" xyz="0.0 -0.0024 -0.05"/>
      <geometry>
        <mesh filename="file:///home/coconutros2/elephant_ws/install/mycobot_320_description/share/mycobot_320_description/meshes/mycobot_320/link4.dae"/>
      </geometry>
    </visual>
    <collision>
      <origin rpy=" 1.5708 1.5708 0" xyz="0.0 -0.0024 -0.05"/>
      <geometry>
        <mesh filename="file:///home/coconutros2/elephant_ws/install/mycobot_320_description/share/mycobot_320_description/meshes/mycobot_320/link4.dae"/>
      </geometry>
    </collision>
  </link>
  <link name="link5">
    <visual>
      <origin rpy=" 0  0 -1.5708" xyz="0.0 0.0 -0.05 "/>
      <geometry>
        <mesh filename="file:///home/coconutros2/elephant_ws/install/mycobot_320_description/share/mycobot_320_description/meshes/mycobot_320/link5.dae"/>
      </geometry>
    </visual>
    <collision>
      <origin rpy=" 0  0 -1.5708" xyz="0.0 0.0 -0.05 "/>
      <geometry>
        <mesh filename="file:///home/coconutros2/elephant_ws/install/mycobot_320_description/share/mycobot_320_description/meshes/mycobot_320/link5.dae"/>
      </geometry>
    </collision>
  </link>
  <link name="link6">
    <visual>
      <origin rpy=" 1.5708 1.5708 0" xyz="0.0 0.0 -0.0115 "/>
      <geometry>
        <mesh filename="file:///home/coconutros2/elephant_ws/install/mycobot_320_description/share/mycobot_320_description/meshes/mycobot_320/link6.dae"/>
      </geometry>
    </visual>
    <collision>
      <origin rpy=" 1.5708 1.5708 0" xyz="0.0 0.0 -0.0115 "/>
      <geometry>
        <mesh filename="file:///home/coconutros2/elephant_ws/install/mycobot_320_description/share/mycobot_320_description/meshes/mycobot_320/link6.dae"/>
      </geometry>
    </collision>
  </link>
  <!-- base_joint fixes base_link to the environment -->
  <joint name="base_joint" type="fixed">
    <origin rpy="0 0 0" xyz="0 0 0"/>
    <parent link="world"/>
    <child link="base_link"/>
  </joint>
  <!-- joints - main serial chain -->
  <joint name="joint1" type="revolute">
    <parent link="base_link"/>
    <child link="link1"/>
    <origin rpy="0 0 0" xyz="0 0 0.173"/>
    <axis xyz="0 0 1"/>
    <limit effort="1000.0" lower="-2.93" upper="2.93" velocity="0.0"/>
    <dynamics damping="0" friction="0"/>
  </joint>
  <joint name="joint2" type="revolute">
    <parent link="link1"/>
    <child link="link2"/>
    <origin rpy="0 -1.57 1.57" xyz="0 -0.086 0"/>
    <axis xyz="0 0 1"/>
    <limit effort="1000.0" lower="-2.3544491609403506" upper="2.3544491609403506" velocity="0.0"/>
    <dynamics damping="0" friction="0"/>
  </joint>
  <joint name="joint3" type="revolute">
    <parent link="link2"/>
    <child link="link3"/>
    <origin rpy="0 0 0" xyz="0.136 0 -0.086"/>
    <axis xyz="0 0 1"/>
    <limit effort="1000.0" lower="-2.52" upper="2.52" velocity="0.0"/>
    <dynamics damping="0" friction="0"/>
  </joint>
  <joint name="joint4" type="revolute">
    <parent link="link3"/>
    <child link="link4"/>
    <origin rpy="0 0 1.57" xyz="0.12 0 0.082"/>
    <axis xyz="0 0 1"/>
    <limit effort="1000.0" lower="-2.58" upper="2.58" velocity="0.0"/>
    <dynamics damping="0" friction="0"/>
  </joint>
  <joint name="joint5" type="revolute">
    <parent link="link4"/>
    <child link="link5"/>
    <origin rpy="1.57 0 0" xyz="0 -0.094 0"/>
    <axis xyz="0 0 1"/>
    <limit effort="1000.0" lower="-2.93" upper="2.93" velocity="0.0"/>
    <dynamics damping="0" friction="0"/>
  </joint>
  <joint name="joint6" type="revolute">
    <parent link="link5"/>
    <child link="link6"/>
    <origin rpy="-1.57 0 0" xyz="0 0.055 0"/>
    <axis xyz="0 0 1"/>
    <limit effort="1000.0" lower="-3.13" upper="3.13" velocity="0.0"/>
    <dynamics damping="0" friction="0"/>
  </joint>
  <!-- ROS-Industrial 'tool0' frame - all-zeros tool frame -->
  <link name="tool0"/>
  <joint name="link6-tool0" type="fixed">
    <!-- default toolframe - X+ left, Y+ up, Z+ front -->
    <origin rpy="0 0 0" xyz="0 0 0.075"/>
    <parent link="link6"/>
    <child link="tool0"/>
  </joint>
</robot>
